[2024-05-15T00:05:04.695+0000] {taskinstance.py:1979} INFO - Dependencies all met for dep_context=non-requeueable deps ti=<TaskInstance: load_data.check_environment_setup scheduled__2024-05-14T00:00:00+00:00 [queued]>
[2024-05-15T00:05:04.706+0000] {taskinstance.py:1979} INFO - Dependencies all met for dep_context=requeueable deps ti=<TaskInstance: load_data.check_environment_setup scheduled__2024-05-14T00:00:00+00:00 [queued]>
[2024-05-15T00:05:04.707+0000] {taskinstance.py:2193} INFO - Starting attempt 2 of 2
[2024-05-15T00:05:04.755+0000] {taskinstance.py:2217} INFO - Executing <Task(PythonOperator): check_environment_setup> on 2024-05-14 00:00:00+00:00
[2024-05-15T00:05:04.764+0000] {standard_task_runner.py:60} INFO - Started process 5568 to run task
[2024-05-15T00:05:04.776+0000] {standard_task_runner.py:87} INFO - Running: ['***', 'tasks', 'run', 'load_data', 'check_environment_setup', 'scheduled__2024-05-14T00:00:00+00:00', '--job-id', '11', '--raw', '--subdir', 'DAGS_FOLDER/load_data.py', '--cfg-path', '/tmp/tmpsezj1ypp']
[2024-05-15T00:05:04.780+0000] {standard_task_runner.py:88} INFO - Job 11: Subtask check_environment_setup
[2024-05-15T00:05:04.893+0000] {task_command.py:423} INFO - Running <TaskInstance: load_data.check_environment_setup scheduled__2024-05-14T00:00:00+00:00 [running]> on host a6210a3692b3
[2024-05-15T00:05:05.078+0000] {taskinstance.py:2513} INFO - Exporting env vars: AIRFLOW_CTX_DAG_OWNER='***' AIRFLOW_CTX_DAG_ID='load_data' AIRFLOW_CTX_TASK_ID='check_environment_setup' AIRFLOW_CTX_EXECUTION_DATE='2024-05-14T00:00:00+00:00' AIRFLOW_CTX_TRY_NUMBER='2' AIRFLOW_CTX_DAG_RUN_ID='scheduled__2024-05-14T00:00:00+00:00'
[2024-05-15T00:05:05.081+0000] {taskinstance.py:2731} ERROR - Task failed with exception
Traceback (most recent call last):
  File "/home/airflow/.local/lib/python3.8/site-packages/airflow/models/taskinstance.py", line 444, in _execute_task
    result = _execute_callable(context=context, **execute_callable_kwargs)
  File "/home/airflow/.local/lib/python3.8/site-packages/airflow/models/taskinstance.py", line 414, in _execute_callable
    return execute_callable(context=context, **execute_callable_kwargs)
  File "/home/airflow/.local/lib/python3.8/site-packages/airflow/operators/python.py", line 200, in execute
    return_value = self.execute_callable()
  File "/home/airflow/.local/lib/python3.8/site-packages/airflow/operators/python.py", line 217, in execute_callable
    return self.python_callable(*self.op_args, **self.op_kwargs)
  File "/opt/airflow/dags/load_data.py", line 20, in check_environment_setup
    raise Exception(f"Les fichiers suivants sont manquants : {', '.join(missing_files)}")
Exception: Les fichiers suivants sont manquants : model_training_promotion.py
[2024-05-15T00:05:05.093+0000] {taskinstance.py:1149} INFO - Marking task as FAILED. dag_id=load_data, task_id=check_environment_setup, execution_date=20240514T000000, start_date=20240515T000504, end_date=20240515T000505
[2024-05-15T00:05:05.170+0000] {standard_task_runner.py:107} ERROR - Failed to execute job 11 for task check_environment_setup (Les fichiers suivants sont manquants : model_training_promotion.py; 5568)
[2024-05-15T00:05:05.195+0000] {local_task_job_runner.py:234} INFO - Task exited with return code 1
[2024-05-15T00:05:05.239+0000] {taskinstance.py:3312} INFO - 0 downstream tasks scheduled from follow-on schedule check
