[2024-05-15T09:09:17.949+0000] {taskinstance.py:1979} INFO - Dependencies all met for dep_context=non-requeueable deps ti=<TaskInstance: load_data.check_environment_setup manual__2024-05-15T09:09:14.075520+00:00 [queued]>
[2024-05-15T09:09:17.976+0000] {taskinstance.py:1979} INFO - Dependencies all met for dep_context=requeueable deps ti=<TaskInstance: load_data.check_environment_setup manual__2024-05-15T09:09:14.075520+00:00 [queued]>
[2024-05-15T09:09:17.977+0000] {taskinstance.py:2193} INFO - Starting attempt 1 of 2
[2024-05-15T09:09:18.014+0000] {taskinstance.py:2217} INFO - Executing <Task(PythonOperator): check_environment_setup> on 2024-05-15 09:09:14.075520+00:00
[2024-05-15T09:09:18.030+0000] {standard_task_runner.py:60} INFO - Started process 150 to run task
[2024-05-15T09:09:18.041+0000] {standard_task_runner.py:87} INFO - Running: ['***', 'tasks', 'run', 'load_data', 'check_environment_setup', 'manual__2024-05-15T09:09:14.075520+00:00', '--job-id', '23', '--raw', '--subdir', 'DAGS_FOLDER/load_data.py', '--cfg-path', '/tmp/tmpbpvxd_8g']
[2024-05-15T09:09:18.053+0000] {standard_task_runner.py:88} INFO - Job 23: Subtask check_environment_setup
[2024-05-15T09:09:18.216+0000] {task_command.py:423} INFO - Running <TaskInstance: load_data.check_environment_setup manual__2024-05-15T09:09:14.075520+00:00 [running]> on host a6210a3692b3
[2024-05-15T09:09:18.377+0000] {taskinstance.py:2513} INFO - Exporting env vars: AIRFLOW_CTX_DAG_OWNER='***' AIRFLOW_CTX_DAG_ID='load_data' AIRFLOW_CTX_TASK_ID='check_environment_setup' AIRFLOW_CTX_EXECUTION_DATE='2024-05-15T09:09:14.075520+00:00' AIRFLOW_CTX_TRY_NUMBER='1' AIRFLOW_CTX_DAG_RUN_ID='manual__2024-05-15T09:09:14.075520+00:00'
[2024-05-15T09:09:18.378+0000] {taskinstance.py:2731} ERROR - Task failed with exception
Traceback (most recent call last):
  File "/home/airflow/.local/lib/python3.8/site-packages/airflow/models/taskinstance.py", line 444, in _execute_task
    result = _execute_callable(context=context, **execute_callable_kwargs)
  File "/home/airflow/.local/lib/python3.8/site-packages/airflow/models/taskinstance.py", line 414, in _execute_callable
    return execute_callable(context=context, **execute_callable_kwargs)
  File "/home/airflow/.local/lib/python3.8/site-packages/airflow/operators/python.py", line 200, in execute
    return_value = self.execute_callable()
  File "/home/airflow/.local/lib/python3.8/site-packages/airflow/operators/python.py", line 217, in execute_callable
    return self.python_callable(*self.op_args, **self.op_kwargs)
  File "/opt/airflow/dags/load_data.py", line 20, in check_environment_setup
    raise Exception(f"Les fichiers suivants sont manquants : {', '.join(missing_files)}")
Exception: Les fichiers suivants sont manquants : model_training_promotion.py
[2024-05-15T09:09:18.394+0000] {taskinstance.py:1149} INFO - Marking task as UP_FOR_RETRY. dag_id=load_data, task_id=check_environment_setup, execution_date=20240515T090914, start_date=20240515T090917, end_date=20240515T090918
[2024-05-15T09:09:18.413+0000] {standard_task_runner.py:107} ERROR - Failed to execute job 23 for task check_environment_setup (Les fichiers suivants sont manquants : model_training_promotion.py; 150)
[2024-05-15T09:09:18.436+0000] {local_task_job_runner.py:234} INFO - Task exited with return code 1
[2024-05-15T09:09:18.471+0000] {taskinstance.py:3312} INFO - 0 downstream tasks scheduled from follow-on schedule check
