[2024-05-15T00:15:58.818+0000] {taskinstance.py:1979} INFO - Dependencies all met for dep_context=non-requeueable deps ti=<TaskInstance: transform_data.transform_data_task manual__2024-05-15T00:10:53.421196+00:00 [queued]>
[2024-05-15T00:15:58.829+0000] {taskinstance.py:1979} INFO - Dependencies all met for dep_context=requeueable deps ti=<TaskInstance: transform_data.transform_data_task manual__2024-05-15T00:10:53.421196+00:00 [queued]>
[2024-05-15T00:15:58.830+0000] {taskinstance.py:2193} INFO - Starting attempt 2 of 2
[2024-05-15T00:15:58.851+0000] {taskinstance.py:2217} INFO - Executing <Task(PythonOperator): transform_data_task> on 2024-05-15 00:10:53.421196+00:00
[2024-05-15T00:15:58.861+0000] {standard_task_runner.py:60} INFO - Started process 5756 to run task
[2024-05-15T00:15:58.872+0000] {standard_task_runner.py:87} INFO - Running: ['***', 'tasks', 'run', 'transform_data', 'transform_data_task', 'manual__2024-05-15T00:10:53.421196+00:00', '--job-id', '20', '--raw', '--subdir', 'DAGS_FOLDER/transform_data.py', '--cfg-path', '/tmp/tmp7g2avwvt']
[2024-05-15T00:15:58.876+0000] {standard_task_runner.py:88} INFO - Job 20: Subtask transform_data_task
[2024-05-15T00:15:58.988+0000] {task_command.py:423} INFO - Running <TaskInstance: transform_data.transform_data_task manual__2024-05-15T00:10:53.421196+00:00 [running]> on host a6210a3692b3
[2024-05-15T00:15:59.104+0000] {taskinstance.py:2513} INFO - Exporting env vars: AIRFLOW_CTX_DAG_OWNER='***' AIRFLOW_CTX_DAG_ID='transform_data' AIRFLOW_CTX_TASK_ID='transform_data_task' AIRFLOW_CTX_EXECUTION_DATE='2024-05-15T00:10:53.421196+00:00' AIRFLOW_CTX_TRY_NUMBER='2' AIRFLOW_CTX_DAG_RUN_ID='manual__2024-05-15T00:10:53.421196+00:00'
[2024-05-15T00:15:59.106+0000] {taskinstance.py:2731} ERROR - Task failed with exception
Traceback (most recent call last):
  File "/home/airflow/.local/lib/python3.8/site-packages/airflow/models/taskinstance.py", line 444, in _execute_task
    result = _execute_callable(context=context, **execute_callable_kwargs)
  File "/home/airflow/.local/lib/python3.8/site-packages/airflow/models/taskinstance.py", line 414, in _execute_callable
    return execute_callable(context=context, **execute_callable_kwargs)
  File "/home/airflow/.local/lib/python3.8/site-packages/airflow/operators/python.py", line 200, in execute
    return_value = self.execute_callable()
  File "/home/airflow/.local/lib/python3.8/site-packages/airflow/operators/python.py", line 217, in execute_callable
    return self.python_callable(*self.op_args, **self.op_kwargs)
  File "/opt/airflow/dags/transform_data.py", line 10, in transform_data
    postgres_host = os.environ.get('AZURE_DB_HOST')
NameError: name 'os' is not defined
[2024-05-15T00:15:59.116+0000] {taskinstance.py:1149} INFO - Marking task as FAILED. dag_id=transform_data, task_id=transform_data_task, execution_date=20240515T001053, start_date=20240515T001558, end_date=20240515T001559
[2024-05-15T00:15:59.135+0000] {standard_task_runner.py:107} ERROR - Failed to execute job 20 for task transform_data_task (name 'os' is not defined; 5756)
[2024-05-15T00:15:59.168+0000] {local_task_job_runner.py:234} INFO - Task exited with return code 1
[2024-05-15T00:15:59.192+0000] {taskinstance.py:3312} INFO - 0 downstream tasks scheduled from follow-on schedule check
