[2024-05-15T00:00:03.979+0000] {taskinstance.py:1979} INFO - Dependencies all met for dep_context=non-requeueable deps ti=<TaskInstance: transform_data.transform_data_task scheduled__2024-05-14T00:00:00+00:00 [queued]>
[2024-05-15T00:00:03.986+0000] {taskinstance.py:1979} INFO - Dependencies all met for dep_context=requeueable deps ti=<TaskInstance: transform_data.transform_data_task scheduled__2024-05-14T00:00:00+00:00 [queued]>
[2024-05-15T00:00:03.987+0000] {taskinstance.py:2193} INFO - Starting attempt 1 of 2
[2024-05-15T00:00:04.000+0000] {taskinstance.py:2217} INFO - Executing <Task(PythonOperator): transform_data_task> on 2024-05-14 00:00:00+00:00
[2024-05-15T00:00:04.007+0000] {standard_task_runner.py:60} INFO - Started process 5493 to run task
[2024-05-15T00:00:04.013+0000] {standard_task_runner.py:87} INFO - Running: ['***', 'tasks', 'run', 'transform_data', 'transform_data_task', 'scheduled__2024-05-14T00:00:00+00:00', '--job-id', '10', '--raw', '--subdir', 'DAGS_FOLDER/transform_data.py', '--cfg-path', '/tmp/tmpcagw4yo4']
[2024-05-15T00:00:04.016+0000] {standard_task_runner.py:88} INFO - Job 10: Subtask transform_data_task
[2024-05-15T00:00:04.075+0000] {task_command.py:423} INFO - Running <TaskInstance: transform_data.transform_data_task scheduled__2024-05-14T00:00:00+00:00 [running]> on host a6210a3692b3
[2024-05-15T00:00:04.152+0000] {taskinstance.py:2513} INFO - Exporting env vars: AIRFLOW_CTX_DAG_OWNER='***' AIRFLOW_CTX_DAG_ID='transform_data' AIRFLOW_CTX_TASK_ID='transform_data_task' AIRFLOW_CTX_EXECUTION_DATE='2024-05-14T00:00:00+00:00' AIRFLOW_CTX_TRY_NUMBER='1' AIRFLOW_CTX_DAG_RUN_ID='scheduled__2024-05-14T00:00:00+00:00'
[2024-05-15T00:00:04.154+0000] {taskinstance.py:2731} ERROR - Task failed with exception
Traceback (most recent call last):
  File "/home/airflow/.local/lib/python3.8/site-packages/airflow/models/taskinstance.py", line 444, in _execute_task
    result = _execute_callable(context=context, **execute_callable_kwargs)
  File "/home/airflow/.local/lib/python3.8/site-packages/airflow/models/taskinstance.py", line 414, in _execute_callable
    return execute_callable(context=context, **execute_callable_kwargs)
  File "/home/airflow/.local/lib/python3.8/site-packages/airflow/operators/python.py", line 200, in execute
    return_value = self.execute_callable()
  File "/home/airflow/.local/lib/python3.8/site-packages/airflow/operators/python.py", line 217, in execute_callable
    return self.python_callable(*self.op_args, **self.op_kwargs)
  File "/opt/airflow/dags/transform_data.py", line 10, in transform_data
    postgres_host = os.environ.get('AZURE_DB_HOST')
NameError: name 'os' is not defined
[2024-05-15T00:00:04.162+0000] {taskinstance.py:1149} INFO - Marking task as UP_FOR_RETRY. dag_id=transform_data, task_id=transform_data_task, execution_date=20240514T000000, start_date=20240515T000003, end_date=20240515T000004
[2024-05-15T00:00:04.174+0000] {standard_task_runner.py:107} ERROR - Failed to execute job 10 for task transform_data_task (name 'os' is not defined; 5493)
[2024-05-15T00:00:04.185+0000] {local_task_job_runner.py:234} INFO - Task exited with return code 1
[2024-05-15T00:00:04.201+0000] {taskinstance.py:3312} INFO - 0 downstream tasks scheduled from follow-on schedule check
